Workbook

Sheet Client_Master
A1: Client_ID | B1: Legal_Name | C1: Entity_Type | D1: Country | E1: Region | F1: Business_Unit | G1: Ownership_Structure | H1: UBO_Identified | I1: PEP_Connection | J1: Adverse_Media | K1: Sanctions_Screening | L1: Last_Review_Date | N1: Legend
A2: CL0001 | B2: Maple Opportunities Fund LP | C2: Investment Fund | D2: Canada | E2: Canada | F2: Equities | G2: Complex | H2: N | I2: N | J2: None | K2: Clear | L2: 45020 | N2: Yellow row 2 = example only, delete it in Step 2.
A3: CL0002 | B3: Granite Teachers Pension Plan | C3: Pension Fund | D3: United States | E3: US | F3: Equities | G3: Simple | H3: Y | I3: N | J3: None | K3: Clear | L3: 45975 | N3: Columns C, E–K have dropdowns.
A4: CL0003 | B4: Redstone Opportunities Fund Ltd | C4: Investment Fund | D4: Japan | E4: APAC | F4: Equities | G4: Simple | H4: Y | I4: N | J4: None | K4: Clear | L4: 46293 | N4: Hover a header to see what it means.
A5: CL0004 | B5: Westmark Multi-Strategy Fund Ltd | C5: Investment Fund | D5: Canada | E5: Canada | F5: Equities | G5: Simple | H5: Y | I5: N | J5: None | K5: Clear | L5: 45334
A6: CL0005 | B6: Ironwood Equity Income Fund Ltd | C6: Investment Fund | D6: Canada | E6: Canada | F6: FX | G6: Simple | H6: Y | I6: N | J6: None | K6: Clear | L6: 45698
A7: CL0006 | B7: Clearview Securities Inc. | C7: Bank | D7: Canada | E7: Canada | F7: Equities | G7: Simple | H7: Y | I7: N | J7: None | K7: Clear | L7: 45387 | N7: =COUNTA(A2:A201) -> 200
A8: CL0007 | B8: Kingsway Partners LLC | C8: Corporation | D8: United States | E8: US | F8: Fixed Income | G8: Simple | H8: Y | I8: N | J8: None | K8: Clear | L8: 44881 | N8: =COUNTBLANK(L2:L201) -> 3
A9: CL0008 | B9: Cedar Credit Fund LP | C9: Investment Fund | D9: British Virgin Islands | E9: Offshore | F9: Fixed Income | G9: Complex | H9: Y | I9: N | J9: None | K9: Clear | L9: 45404 | N9: =COUNTBLANK(H2:H201) -> 2
A10: CL0009 | B10: Meridian Workers Pension Plan | C10: Pension Fund | D10: Australia | E10: APAC | F10: Equities | G10: Simple | H10: Y | I10: N | J10: None | K10: Clear | L10: 46183 | N10: =COUNTIF(K2:K201,"Potential Match") -> 6
A11: CL0010 | B11: Aurora Municipal Pension Plan | C11: Pension Fund | D11: Canada | E11: Canada | F11: Equities | G11: Simple | H11: Y | I11: N | J11: None | K11: Clear | L11: 45890 | N11: =COUNTIF(I2:I201,"Y") -> 10
A12: CL0011 | B12: Pinecrest Charitable Trust | C12: Trust | D12: Bermuda | E12: Offshore | F12: Fixed Income | G12: Complex | H12: Y | I12: N | J12: None | K12: Clear | L12: 45060 | N12: CL0003
A13: CL0012 | B13: Clearview Asset Management LLC | C13: Corporation | D13: United States | E13: US | F13: Equities | G13: Simple | H13: Y | I13: N | J13: None | K13: Clear | L13: 46134 | N13: CL0038
A14: CL0013 | B14: Westmark Opportunities Fund LP | C14: Investment Fund | D14: Canada | E14: Canada | F14: Equities | G14: Simple | H14: Y | I14: N | J14: None | K14: Clear | L14: 45536 | N14: CL0091
A15: CL0014 | B15: Aurora Employees Pension Plan | C15: Pension Fund | D15: Luxembourg | E15: Europe | F15: FX | G15: Simple | H15: Y | I15: N | J15: None | K15: Clear | L15: 45445 | N15: CL0120
A16: CL0015 | B16: Aurora Legacy Trust | C16: Trust | D16: Cayman Islands | E16: Offshore | F16: FX | G16: Complex | H16: Y | I16: N | J16: None | K16: Clear | L16: 45234
A17: CL0016 | B17: Atlas Global Macro Fund Ltd | C17: Investment Fund | D17: Ireland | E17: Europe | F17: Fixed Income | G17: Complex | H17: N | I17: Y | J17: None | K17: Clear | L17: 45540
A18: CL0017 | B18: Silverline Family Trust | C18: Trust | D18: United States | E18: US | F18: FX | G18: Complex | H18: Y | I18: N | J18: None | K18: Clear | L18: 44838
A19: CL0018 | B19: Harbour Trust Company LLC | C19: Bank | D19: United States | E19: US | F19: Fixed Income | G19: Complex | H19: Y | I19: N | J19: None | K19: Clear | L19: 46137
A20: CL0019 | B20: Brightwater Opportunities Fund LP | C20: Investment Fund | D20: Canada | E20: Canada | F20: Equities | G20: Complex | H20: N | I20: N | J20: Minor | K20: Clear | L20: 46055
A21: CL0020 | B21: North Opportunities Fund LP | C21: Investment Fund | D21: Bermuda | E21: Offshore | F21: Equities | G21: Complex | H21: Y | I21: N | J21: Minor | K21: Clear | L21: 45350
A22: CL0021 | B22: Ironwood Securities Inc. | C22: Bank | D22: Canada | E22: Canada | F22: Fixed Income | G22: Simple | H22: Y | I22: N | J22: None | K22: Clear | L22: 45893
A23: CL0022 | B23: Eastbay Multi-Strategy Fund LP | C23: Investment Fund | D23: United States | E23: US | F23: Equities | G23: Simple | H23: Y | I23: N | J23: None | K23: Clear | L23: 46102
A24: CL0023 | B24: Fairhaven Energy B.V. | C24: Corporation | D24: Netherlands | E24: Europe | F24: Equities | G24: Simple | H24: Y | I24: N | J24: Minor | K24: Clear | L24: 44921
A25: CL0024 | B25: North Opportunities Fund Ltd | C25: Investment Fund | D25: Netherlands | E25: Europe | F25: Fixed Income | G25: Complex | H25: Y | I25: N | J25: None | K25: Clear | L25: 45814
A26: CL0025 | B26: Meridian Trust Company LLC | C26: Bank | D26: United States | E26: US | F26: Equities | G26: Simple | H26: Y | I26: N | J26: None | K26: Clear | L26: 46209
A27: CL0026 | B27: Bluewater Holdings Inc. | C27: Corporation | D27: Canada | E27: Canada | F27: FX | G27: Simple | H27: Y | I27: N | J27: None | K27: Clear | L27: 45792
... A73: CL0072 | B73: Cedar Opportunities Fund Ltd | C73: Investment Fund | D73: Cayman Islands | E73: Offshore | F73: Fixed Income | G73: Complex | H73: Y | I73: N | J73: None | K73: Clear | L73: 46215
A74: CL0073 | B74: Bluewater Securities Inc. | C74: Bank | D74: Canada | E74: Canada | F74: Equities | G74: Simple | H74: Y | I74: N | J74: None | K74: Clear
A75: CL0074 | B75: Pinecrest Partners Inc. | C75: Corporation | D75: Canada | E75: Canada | F75: FX | G75: Simple | H75: Y | I75: N | J75: None | K75: Clear | L75: 45044
A76: CL0075 | B76: Silverline Employees Pension Plan | C76: Pension Fund | D76: Canada | E76: Canada | F76: Equities | G76: Simple | H76: Y | I76: N | J76: None | K76: Clear | L76: 44988
A77: CL0076 | B77: Meridian Opportunities Fund LP | C77: Investment Fund | D77: United States | E77: US | F77: Equities | G77: Simple | H77: Y | I77: N | J77: None | K77: Clear | L77: 45357
A78: CL0077 | B78: Ironwood Workers Pension Plan | C78: Pension Fund | D78: Canada | E78: Canada | F78: Fixed Income | G78: Simple | H78: Y | I78: N | J78: None | K78: Clear | L78: 44964
A79: CL0078 | B79: Summit Trust Company LLC | C79: Bank | D79: United States | E79: US | F79: Fixed Income | G79: Simple | H79: Y | I79: N | J79: None | K79: Clear | L79: 45690
A80: CL0079 | B80: Lakeshore Securities Ltd | C80: Bank | D80: British Virgin Islands | E80: Offshore | F80: Fixed Income | G80: Complex | H80: Y | I80: N | J80: None | K80: Clear | L80: 44847
A81: CL0080 | B81: Harbour Equity Income Fund Ltd | C81: Investment Fund | D81: United States | E81: US | F81: FX | G81: Complex | H81: N | I81: Y | J81: None | K81: Clear | L81: 45017
A82: CL0081 | B82: Aurora Bank Ltd | C82: Bank | D82: United Kingdom | E82: UK | F82: FX | G82: Simple | H82: Y | I82: N | J82: None | K82: Clear | L82: 45239
A83: CL0082 | B83: Westmark Legacy Trust | C83: Trust | D83: Canada | E83: Canada | F83: FX | G83: Complex | H83: Y | I83: N | J83: Minor | K83: Clear | L83: 45163
A84: CL0083 | B84: Oakridge Global Macro Fund Ltd | C84: Investment Fund | D84: United Kingdom | E84: UK | F84: Equities | G84: Complex | H84: Y | I84: N | J84: None | K84: Clear | L84: 45340
A85: CL0084 | B85: Pinecrest Multi-Strategy Fund Ltd | C85: Investment Fund | D85: Cayman Islands | E85: Offshore | F85: Fixed Income | G85: Complex | H85: Y | I85: N | J85: None | K85: Clear | L85: 46184
...

Sheet Change_Log
A1: Client_ID | B1: Field | C1: Old_Value | D1: New_Value | E1: Date | F1: Reason
A2: CL0003 | B2: Region | C2: Europe | D2: APAC | E2: 46314 | F2: Region did not match country (Japan)
A3: CL0038 | B3: Region | C3: APAC | D3: Europe | E3: 46314 | F3: Region did not match country (Germany)
A4: CL0091 | B4: Region | C4: UK | D4: APAC | E4: 46314 | F4: Region did not match country (Singapore)
A5: CL0120 | B5: Region | C5: US | D5: Europe | E5: 46314 | F5: Region did not match country (France)

Sheet Risk_Scoring
A1: Client_ID | B1: Jurisdiction_Score | C1: Entity_Score | D1: Ownership_Score | E1: UBO_Score | F1: PEP_Score | G1: Media_Score | H1: Total_Score | I1: Sanctions_Flag | J1: Risk_Rating | L1: Jurisdiction | M1: Points
A2: =Client_Master!A2 -> CL0001 | B2: =VLOOKUP(Client_Master!E2,$L$2:$M$7,2,FALSE) -> 0 | C2: =VLOOKUP(Client_Master!C2,$L$10:$M$14,2,FALSE) -> 2 | L2: Canada | M2: 0
A3: =Client_Master!A3 -> CL0002 | B3: =VLOOKUP(Client_Master!E3,$L$2:$M$7,2,FALSE) -> 0 | C3: =VLOOKUP(Client_Master!C3,$L$10:$M$14,2,FALSE) -> 0 | L3: US | M3: 0
A4: =Client_Master!A4 -> CL0003 | B4: =VLOOKUP(Client_Master!E4,$L$2:$M$7,2,FALSE) -> 1 | C4: =VLOOKUP(Client_Master!C4,$L$10:$M$14,2,FALSE) -> 2 | L4: UK | M4: 0
A5: =Client_Master!A5 -> CL0004 | B5: =VLOOKUP(Client_Master!E5,$L$2:$M$7,2,FALSE) -> 0 | C5: =VLOOKUP(Client_Master!C5,$L$10:$M$14,2,FALSE) -> 2 | L5: Europe | M5: 1
A6: =Client_Master!A6 -> CL0005 | B6: =VLOOKUP(Client_Master!E6,$L$2:$M$7,2,FALSE) -> 0 | C6: =VLOOKUP(Client_Master!C6,$L$10:$M$14,2,FALSE) -> 2 | L6: APAC | M6: 1
A7: =Client_Master!A7 -> CL0006 | B7: =VLOOKUP(Client_Master!E7,$L$2:$M$7,2,FALSE) -> 0 | C7: =VLOOKUP(Client_Master!C7,$L$10:$M$14,2,FALSE) -> 0 | L7: Offshore | M7: 3
A8: =Client_Master!A8 -> CL0007 | B8: =VLOOKUP(Client_Master!E8,$L$2:$M$7,2,FALSE) -> 0 | C8: =VLOOKUP(Client_Master!C8,$L$10:$M$14,2,FALSE) -> 1
A9: =Client_Master!A9 -> CL0008 | B9: =VLOOKUP(Client_Master!E9,$L$2:$M$7,2,FALSE) -> 3 | C9: =VLOOKUP(Client_Master!C9,$L$10:$M$14,2,FALSE) -> 2 | L9: Entity_Type | M9: Points
A10: =Client_Master!A10 -> CL0009 | B10: =VLOOKUP(Client_Master!E10,$L$2:$M$7,2,FALSE) -> 1 | C10: =VLOOKUP(Client_Master!C10,$L$10:$M$14,2,FALSE) -> 0 | L10: Bank | M10: 0
A11: =Client_Master!A11 -> CL0010 | B11: =VLOOKUP(Client_Master!E11,$L$2:$M$7,2,FALSE) -> 0 | C11: =VLOOKUP(Client_Master!C11,$L$10:$M$14,2,FALSE) -> 0 | L11: Pension Fund | M11: 0
A12: =Client_Master!A12 -> CL0011 | B12: =VLOOKUP(Client_Master!E12,$L$2:$M$7,2,FALSE) -> 3 | C12: =VLOOKUP(Client_Master!C12,$L$10:$M$14,2,FALSE) -> 2 | L12: Corporation | M12: 1
A13: =Client_Master!A13 -> CL0012 | B13: =VLOOKUP(Client_Master!E13,$L$2:$M$7,2,FALSE) -> 0 | C13: =VLOOKUP(Client_Master!C13,$L$10:$M$14,2,FALSE) -> 1 | L13: Investment Fund | M13: 2
A14: =Client_Master!A14 -> CL0013 | B14: =VLOOKUP(Client_Master!E14,$L$2:$M$7,2,FALSE) -> 0 | C14: =VLOOKUP(Client_Master!C14,$L$10:$M$14,2,FALSE) -> 2 | L14: Trust | M14: 2
A15: =Client_Master!A15 -> CL0014 | B15: =VLOOKUP(Client_Master!E15,$L$2:$M$7,2,FALSE) -> 1 | C15: =VLOOKUP(Client_Master!C15,$L$10:$M$14,2,FALSE) -> 0
A16: =Client_Master!A16 -> CL0015 | B16: =VLOOKUP(Client_Master!E16,$L$2:$M$7,2,FALSE) -> 3 | C16: =VLOOKUP(Client_Master!C16,$L$10:$M$14,2,FALSE) -> 2
A17: =Client_Master!A17 -> CL0016 | B17: =VLOOKUP(Client_Master!E17,$L$2:$M$7,2,FALSE) -> 1 | C17: =VLOOKUP(Client_Master!C17,$L$10:$M$14,2,FALSE) -> 2
A18: =Client_Master!A18 -> CL0017 | B18: =VLOOKUP(Client_Master!E18,$L$2:$M$7,2,FALSE) -> 0 | C18: =VLOOKUP(Client_Master!C18,$L$10:$M$14,2,FALSE) -> 2
A19: =Client_Master!A19 -> CL0018 | B19: =VLOOKUP(Client_Master!E19,$L$2:$M$7,2,FALSE) -> 0 | C19: =VLOOKUP(Client_Master!C19,$L$10:$M$14,2,FALSE) -> 0
A20: =Client_Master!A20 -> CL0019 | B20: =VLOOKUP(Client_Master!E20,$L$2:$M$7,2,FALSE) -> 0 | C20: =VLOOKUP(Client_Master!C20,$L$10:$M$14,2,FALSE) -> 2
A21: =Client_Master!A21 -> CL0020 | B21: =VLOOKUP(Client_Master!E21,$L$2:$M$7,2,FALSE) -> 3 | C21: =VLOOKUP(Client_Master!C21,$L$10:$M$14,2,FALSE) -> 2
A22: =Client_Master!A22 -> CL0021 | B22: =VLOOKUP(Client_Master!E22,$L$2:$M$7,2,FALSE) -> 0 | C22: =VLOOKUP(Client_Master!C22,$L$10:$M$14,2,FALSE) -> 0
A23: =Client_Master!A23 -> CL0022 | B23: =VLOOKUP(Client_Master!E23,$L$2:$M$7,2,FALSE) -> 0 | C23: =VLOOKUP(Client_Master!C23,$L$10:$M$14,2,FALSE) -> 2
A24: =Client_Master!A24 -> CL0023 | B24: =VLOOKUP(Client_Master!E24,$L$2:$M$7,2,FALSE) -> 1 | C24: =VLOOKUP(Client_Master!C24,$L$10:$M$14,2,FALSE) -> 1
A25: =Client_Master!A25 -> CL0024 | B25: =VLOOKUP(Client_Master!E25,$L$2:$M$7,2,FALSE) -> 1 | C25: =VLOOKUP(Client_Master!C25,$L$10:$M$14,2,FALSE) -> 2
A26: =Client_Master!A26 -> CL0025 | B26: =VLOOKUP(Client_Master!E26,$L$2:$M$7,2,FALSE) -> 0 | C26: =VLOOKUP(Client_Master!C26,$L$10:$M$14,2,FALSE) -> 0
... A201: =Client_Master!A201 -> CL0200 | B201: =VLOOKUP(Client_Master!E201,$L$2:$M$7,2,FALSE) -> 0 | C201: =VLOOKUP(Client_Master!C201,$L$10:$M$14,2,FALSE) -> 1

Sheet Refresh_Queue
A1: Built in Step 4

Sheet Document_Tracker
A1: Built in Step 5

Sheet Escalation_Log
A1: Built in Step 6

Sheet QC_Review
A1: Built in Step 7
